Workbook

Sheet 📋 Index
B2: GROWTH STRATEGIES — FINANCIAL MODEL
B3: Q4 2025 Forensic Audit | Q1 2026 Contribution Margin Forecast | All figures in CAD
B5: KEY FINDINGS — Q4 2025 | E5: WORKBOOK NAVIGATION
B6: Gross Sales | C6: $3,310,451 | E6: 📋 Index | F6: This sheet — overview and navigation
B7: Net Sales | C7: $2,705,296 | E7: 🔍 Q4 Audit | F7: Forensic P&L, daily data, worst day analysis
B8: Total Orders | C8: 15,093 | E8: 📊 Daily Data | F8: Full 91-day daily transaction table
B9: Avg Order Value | C9: $219.35 | E9: 📈 Q1 2026 Forecast | F9: Month-by-month P&L forecast with scenarios
B10: Weighted COGS % | C10: 35.20% | E10: 🧮 Assumptions | F10: All model inputs — change here, flows everywhere
B11: COGS Total | C11: $1,165,221
B12: Shipping Cost | C12: $128,291
B13: Ad Spend | C13: $627,400
B14: Contribution Margin $ | C14: $784,384
B15: Contribution Margin % | C15: 23.69%
B16: Worst Day | C16: Sep 23, 2025
B17: Worst Day CM | C17: ($12,950) / -33.2%
B20: COLOR CODING LEGEND
B21: Blue text | C21: Hardcoded input — you can change these
B22: Black text | C22: Formula / calculated value — do not edit
B23: Green text | C23: Cross-sheet link pulling from another tab
B24: Yellow background | C24: KEY ASSUMPTION — review before use
B25: Green background | C25: Positive / target achieved
B26: Red background | C26: Negative / target missed
B30: Data Sources:
B31: • Gross_sales_over_time_2025-09-17_2025-12-16.csv — Shopify daily sales export
B32: • Marketing_Channel_Performance_Sheet1.csv — Meta/Google/TikTok/Email daily spend & attributed sales
B33: • Sessions_over_time_2025-09-17_2025-12-16.csv — Shopify sessions, conversion rate, bounce rate
B34: • Total_sales_by_product_variant2.csv — SKU-level gross sales and COGS (source of weighted COGS %)
B35: • Total_sales_by_billing_location.csv — Orders by geography (source of total order count)
B36: • Weighted Avg COGS: $1,135,677 COGS / $3,226,515 Gross Sales from product variant file = 35.20%
B37: • Shipping: $8.50 flat cost per order x 15,093 orders = $128,291 (per brief assumption)

Sheet 🔍 Q4 Audit
B1: 🔍 Q4 FORENSIC AUDIT | Sep 17 - Dec 16, 2025
B3: SECTION A — WEIGHTED AVERAGE COGS CALCULATION (Source: product variant CSV)
B4: Metric | C4: Value | D4: Notes / Formula
B5: Total Gross Sales (product variant file) | C5: 3226514.5 | D5: SUM(Gross Sales) where COGS > 0
B6: Total COGS (product variant file) | C6: 1135677.3 | D6: SUM(Cost of goods sold) — actual per SKU
B7: Weighted Avg COGS % of Gross Sales | C7: 0.352 | D7: Total COGS / Total Gross Sales = 35.20%
B8: Gross Sales (daily file — used for P&L) | C8: 3310450.5 | D8: SUM(Gross sales) from daily file
B9: COGS applied to daily file | C9: 1165221.3 | D9: Gross Sales x 35.20% weighted avg COGS %
B11: SECTION B — TRUE CONTRIBUTION MARGIN P&L | Formula: Net Sales - COGS - Shipping - Ad Spend
B12: P&L Line Item | C12: Amount ($) | D12: % of Gross | E12: Notes
B13: GROSS SALES | C13: 3310450.5 | D13: =C13/C13 -> 1 | E13: Sum of all daily gross sales
B14: (Less) Returns | C14: -552351.65 | D14: =C14/C13 -> -0.1668509 | E14: Negative — items returned by customers
B15: (Less) Discounts | C15: -52803.26 | D15: =C15/C13 -> -0.015950476 | E15: Promo codes, discount orders
B16: NET SALES | C16: 2705295.6 | D16: =C16/C13 -> 0.81719862 | E16: Gross Sales + Returns + Discounts
B17: (Less) COGS | C17: -1165221.3 | D17: =C17/C13 -> -0.3519827 | E17: Gross Sales x 35.20% weighted COGS %
B18: (Less) Shipping | C18: -128290.5 | D18: =C18/C13 -> -0.038753185 | E18: 15,093 orders x $8.50 flat cost per order
B19: (Less) Ad Spend | C19: -627400 | D19: =C19/C13 -> -0.18952103 | E19: Meta + Google + TikTok + Email/SMS (all channels)
B20: CONTRIBUTION MARGIN | C20: 784383.79 | D20: =C20/C13 -> 0.23694171 | E20: Net Sales - COGS - Shipping - Ad Spend
B21: (Memo) Merchant Fees (2.5%) | C21: -82761.26 | D21: =C21/C13 -> -0.024999999 | E21: 2.5% of gross — for reference
B22: (Memo) CM after Merchant Fees | C22: 701622.53 | D22: =C22/C13 -> 0.21194171 | E22: CM minus merchant fees — true floor
B25: TRUE CONTRIBUTION MARGIN = $784,384 | 23.69% of Gross Sales | This ALREADY EXCEEDS the 15% CEO target for Q1.
B27: SECTION C — THE 'CASH BURN' DAY | Single Worst Day for Profitability
B28: WORST DAY: September 23, 2025 — Contribution Margin = ($12,950) | -33.2% margin
B29: Gross Sales | C29: 39063.49
B30: Returns (55.1% of gross!) | C30: -21516.07
B31: Net Sales | C31: 17362.43
B32: COGS (35.2% of gross) | C32: 13749.673
B33: Shipping Cost (est.) | C33: 1513
B34: Ad Spend | C34: 15050
B35: CONTRIBUTION MARGIN | C35: -12950.243
B36: CM % of Gross | C36: -0.33151781
B37: Sessions that day | C37: 7558
B38: Revenue Per Session (RPS) | C38: 5.1684956
B39: Period Avg RPS | C39: 5.5082407
B40: RPS vs Period Avg | C40: -0.061679423
B42: WHY IT HAPPENED — Root Cause Analysis:
B43: 1. RETURNS CRISIS: Returns on Sep 23 were $21,516 = 55.1% of that day's gross sales vs the period average return rate of 16.7%.
B44: 2. ROOT CAUSE: The Sep 17-18 launch spike (both days $44K-$97K gross) likely included mass ordering of Scuba Pant and Kirsten Mock Neck Top.
B45: The ~6-day return lag means Sep 23 received the concentrated return wave from that launch event. High-return SKUs shipped en masse, returned en masse.
B46: 3. AD SPEND MISMATCH: $15,050 ad spend on Sep 23 was the 2nd highest single-day spend. With net sales crippled by returns,
...

Sheet 📊 Daily Data
B1: DAILY DATA | All 91 Days | Sep 17 - Dec 16, 2025
B2: Date | C2: Gross Sales | D2: Net Sales | E2: Returns | F2: Discounts | G2: Sessions | H2: Ad Spend | I2: Rptd Revenue | J2: COGS | K2: Est Orders | L2: Ship Cost | M2: Cont. Margin | N2: CM % | O2: RPS | P2: ROAS | Q2: Conv % | R2: Bounce %
B3: 2025-09-17 | C3: 97074.6 | D3: 84236.87 | E3: -12622.23 | F3: -215.5 | G3: 7418 | H3: 5350 | I3: 16050 | J3: 34168.58 | K3: 443 | L3: 3765.5 | M3: 40952.79 | N3: 0.42186927 | O3: 13.086358 | P3: 3 | Q3: 0.038420059 | R3: 0.3899973
B4: 2025-09-18 | C4: 44746.99 | D4: 31587.32 | E4: -12186.48 | F4: -973.19 | G4: 7027 | H4: 4820 | I4: 13660 | J4: 15750.166 | K4: 204 | L4: 1734 | M4: 9283.1536 | N4: 0.20745873 | O4: 6.3678654 | P4: 2.8340249 | Q4: 0.017930838 | R4: 0.42649779
B5: 2025-09-19 | C5: 45629.9 | D5: 37746.52 | E5: -7877.38 | F5: -6 | G5: 10654 | H5: 6580 | I5: 20540 | J5: 16060.935 | K5: 208 | L5: 1768 | M5: 13337.585 | N5: 0.29229923 | O5: 4.2828891 | P5: 3.1215805 | Q5: 0.012108128 | R5: 0.33180026
B6: 2025-09-20 | C6: 57708.4 | D6: 53603.15 | E6: -4047 | F6: -58.25 | G6: 6720 | H6: 5960 | I6: 17780 | J6: 20312.358 | K6: 263 | L6: 2235.5 | M6: 25095.292 | N6: 0.43486376 | O6: 8.5875595 | P6: 2.9832215 | Q6: 0.025 | R6: 0.35877976
B7: 2025-09-21 | C7: 36737.7 | D7: 34462.5 | E7: -2226.4 | F7: -48.8 | G7: 6317 | H7: 5540 | I7: 15620 | J7: 12931.035 | K7: 167 | L7: 1419.5 | M7: 14571.965 | N7: 0.39664881 | O7: 5.8156878 | P7: 2.8194946 | Q7: 0.018679753 | R7: 0.39243312
B8: 2025-09-22 | C8: 33192.81 | D8: 27274.66 | E8: -5851.9 | F8: -66.25 | G8: 6176 | H8: 5180 | I8: 13995 | J8: 11683.295 | K8: 151 | L8: 1283.5 | M8: 9127.8651 | N8: 0.27499525 | O8: 5.3744835 | P8: 2.7017375 | Q8: 0.015867876 | R8: 0.41871762
B9: 2025-09-23 | C9: 39063.49 | D9: 17362.43 | E9: -21516.07 | F9: -184.99 | G9: 7558 | H9: 15050 | I9: 53950 | J9: 13749.673 | K9: 178 | L9: 1513 | M9: -12950.243 | N9: -0.33151781 | O9: 5.1684956 | P9: 3.5847176 | Q9: 0.015347976 | R9: 0.40685366
B10: 2025-09-24 | C10: 52284.05 | D10: 39224.33 | E10: -12233.12 | F10: -826.6 | G10: 7502 | H10: 6670 | I10: 21140 | J10: 18403.081 | K10: 238 | L10: 2023 | M10: 12128.249 | N10: 0.23196843 | O10: 6.9693482 | P10: 3.1694153 | Q10: 0.020261264 | R10: 0.39376166
B11: 2025-09-25 | C11: 32033.03 | D11: 23639.53 | E11: -8393.5 | F11: 0 | G11: 7033 | H11: 6050 | I11: 18080 | J11: 11275.072 | K11: 146 | L11: 1241 | M11: 5073.4576 | N11: 0.15838207 | O11: 4.5546751 | P11: 2.9884298 | Q11: 0.015071804 | R11: 0.41347931
B12: 2025-09-26 | C12: 36977.78 | D12: 29161.35 | E12: -7816.43 | F12: 0 | G12: 10397 | H12: 7390 | I12: 23220 | J12: 13015.539 | K12: 169 | L12: 1436.5 | M12: 7319.3111 | N12: 0.19793809 | O12: 3.5565817 | P12: 3.1420839 | Q12: 0.0094257959 | R12: 0.31441762
B13: 2025-09-27 | C13: 38358.81 | D13: 36016.61 | E13: -2287 | F13: -55.2 | G13: 6610 | H13: 6360 | I13: 18910 | J13: 13501.638 | K13: 175 | L13: 1487.5 | M13: 14667.472 | N13: 0.38237559 | O13: 5.8031483 | P13: 2.9732704 | Q13: 0.014069592 | R13: 0.37579425
B14: 2025-09-28 | C14: 33830.6 | D14: 31149.7 | E14: -2680.9 | F14: 0 | G14: 6162 | H14: 5690 | I14: 15960 | J14: 11907.786 | K14: 154 | L14: 1309 | M14: 12242.914 | N14: 0.36188877 | O14: 5.490198 | P14: 2.8049209 | Q14: 0.014930217 | R14: 0.36449205
... B93: 2025-12-16 | C93: 22413.28 | D93: 19497.78 | E93: -2711.49 | F93: -204.01 | G93: 5648 | H93: 6565 | I93: 17260 | J93: 7889.0868 | K93: 102 | L93: 867 | M93: 4176.6932 | N93: 0.18634904 | O93: 3.9683569 | P93: 2.6290937 | Q93: 0.01575779 | R93: 0.43873938
B94: TOTAL / AVERAGE | C94: =SUM(C3:C93) -> 3310450.5 | D94: =SUM(D3:D93) -> 2705295.6 | E94: =SUM(E3:E93) -> -552351.65 | F94: =SUM(F3:F93) -> -52803.26 | H94: =SUM(H3:H93) -> 627400 | I94: =SUM(I3:I93) -> 1706340 | J94: =SUM(J3:J93) -> 1165221.3 | L94: =SUM(L3:L93) -> 128316 | M94: =SUM(M3:M93) -> 784358.29 | N94: =M94/C94 -> 0.236934

Sheet 🧮 Assumptions
B1: MODEL ASSUMPTIONS | All Blue Cells Are Inputs — Change Here To Update Forecast
B3: Assumption | C3: January 2026 | D3: February 2026 | E3: March 2026 | F3: Notes/Rationale
B4: TRAFFIC ASSUMPTIONS
B5: Total Sessions (monthly) | C5: 42000 | D5: 45000 | E5: 50000 | F5: Q4 avg ~6,500/week = ~28K/mo. Jan typically -30% seasonal dip, ramping through Q1.
B6: Paid Sessions % | C6: 0.6 | D6: 0.58 | E6: 0.55 | F6: 60% paid to start; organic content investment shifts mix by March.
B7: Organic Sessions % | C7: 0.4 | D7: 0.42 | E7: 0.45 | F7: 1 - Paid%. Auto-linked in forecast tab.
B9: CONVERSION & REVENUE ASSUMPTIONS
B10: Conversion Rate | C10: 0.02 | D10: 0.022 | E10: 0.025 | F10: Q4 avg 1.77%. Jan: A/B test live +0.23pp. Feb: +0.43pp. Mar: full uplift to 2.5%.
B11: Average Order Value (AOV) | C11: 225 | D11: 230 | E11: 235 | F11: Q4 AOV $219.35. Bundle strategy and upsells drive gradual increase.
B12: Return Rate (% of gross) | C12: 0.135 | D12: 0.12 | E12: 0.1 | F12: Q4 was 16.7%. SKU audit and sizing guide fix drives: Jan 13.5%, Feb 12%, Mar 10%.
B13: Discount Rate (% of gross) | C13: 0.016 | D13: 0.014 | E13: 0.012 | F13: Q4 was 1.60%. Reducing promo reliance as brand trust and margins improve.
B15: COST ASSUMPTIONS
B16: COGS % (of Gross Sales) | C16: 0.352 | D16: 0.352 | E16: 0.352 | F16: LOCKED at 35.20% weighted avg from product variant CSV. Do not change without new COGS data.
B17: Shipping Cost per Order ($) | C17: 8.5 | D17: 8.5 | E17: 8.5 | F17: Fixed per brief. Review if carrier rates change.
B18: Merchant Fees (% of gross) | C18: 0.025 | D18: 0.025 | E18: 0.025 | F18: 2.5% of gross — Shopify Payments / credit card processing estimate.
B20: MARKETING SPEND ASSUMPTIONS
B21: Total Monthly Ad Spend ($) | C21: 55000 | D21: 60000 | E21: 65000 | F21: Q4 was $627K over 91 days (~$6,895/day). Jan: pullback to optimise. Feb/Mar: scale winners.
B22: Meta % of spend | C22: 0.5 | D22: 0.48 | E22: 0.46 | F22: Reduce Meta from 62% — shift toward Google which has best ROAS (3.39x).
B23: Google % of spend | C23: 0.3 | D23: 0.32 | E23: 0.34 | F23: Scale Google. Expand Shopping campaigns and branded keywords.
B24: TikTok % of spend | C24: 0.12 | D24: 0.12 | E24: 0.12 | F24: Hold flat while testing UGC. Improve attribution tracking first.
B25: Email/SMS % of spend | C25: 0.08 | D25: 0.08 | E25: 0.08 | F25: Increase from 2.6% to 8%. Klaviyo flows + UTMs for full revenue attribution.
B27: SCENARIO TOGGLE NOTE
B28: INSTRUCTIONS: The Q1 2026 Forecast tab uses cross-sheet references to pull all values from this tab. Change any BLUE cell above and the forecast automatically recalculates. The 15% CM CEO target is ALREADY exceeded by Q4 actuals (23.69%). The Q1 forecast targets 15.5% in January, building to 18%+ in March. If the CEO sets a higher target, increase Conversion Rate (row 10) or reduce Return Rate (row 12) first — these have the highest CM leverage.

Sheet 📈 Q1 2026 Forecast
B1: Q1 2026 P&L FORECAST | Jan - Mar 2026 | CEO Target: 15% Contribution Margin
B3: Row Item (all $ in CAD) | C3: January 2026 | D3: February 2026 | E3: March 2026 | F3: Q1 2026 Total | G3: Q4 2025 Actual
B4: Source | C4: Assumptions tab col C | D4: Assumptions tab col D | E4: Assumptions tab col E | F4: Jan + Feb + Mar Total | G4: Verified from CSV data
B5: SECTION 1: TRAFFIC
B6: Total Monthly Sessions | C6: ='🧮 Assumptions'!C5 -> 42000 | D6: ='🧮 Assumptions'!D5 -> 45000 | E6: ='🧮 Assumptions'!E5 -> 50000 | F6: =C6+D6+E6 -> 137000 | G6: 198666
B7: — Paid Sessions | C7: =C6*'🧮 Assumptions'!C6 -> 25200 | D7: =D6*'🧮 Assumptions'!D6 -> 26100 | E7: =E6*'🧮 Assumptions'!E6 -> 27500 | F7: =C7+D7+E7 -> 78800
B8: — Organic Sessions | C8: =C6*'🧮 Assumptions'!C7 -> 16800 | D8: =D6*'🧮 Assumptions'!D7 -> 18900 | E8: =E6*'🧮 Assumptions'!E7 -> 22500 | F8: =C8+D8+E8 -> 58200
B9: Conversion Rate | C9: ='🧮 Assumptions'!C10 -> 0.02 | D9: ='🧮 Assumptions'!D10 -> 0.022 | E9: ='🧮 Assumptions'!E10 -> 0.025 | F9: =C9+D9+E9 -> 0.067 | G9: 0.0177
B10: Estimated Orders | C10: =ROUND(C6*C9,0) -> 840 | D10: =ROUND(D6*D9,0) -> 990 | E10: =ROUND(E6*E9,0) -> 1250 | F10: =C10+D10+E10 -> 3080 | G10: 5031
B11: Average Order Value (AOV) | C11: ='🧮 Assumptions'!C11 -> 225 | D11: ='🧮 Assumptions'!D11 -> 230 | E11: ='🧮 Assumptions'!E11 -> 235 | F11: =C11+D11+E11 -> 690 | G11: 219.35
B13: SECTION 2: REVENUE
B14: Gross Sales | C14: =C10*C11 -> 189000 | D14: =D10*D11 -> 227700 | E14: =E10*E11 -> 293750 | F14: =C14+D14+E14 -> 710450 | G14: 3310451
B15: (Less) Returns | C15: =-C14*'🧮 Assumptions'!C12 -> -25515 | D15: =-D14*'🧮 Assumptions'!D12 -> -27324 | E15: =-E14*'🧮 Assumptions'!E12 -> -29375 | F15: =C15+D15+E15 -> -82214 | G15: -552352
B16: (Less) Discounts | C16: =-C14*'🧮 Assumptions'!C13 -> -3024 | D16: =-D14*'🧮 Assumptions'!D13 -> -3187.8 | E16: =-E14*'🧮 Assumptions'!E13 -> -3525 | F16: =C16+D16+E16 -> -9736.8 | G16: -52803
B17: Net Sales | C17: =C14+C15+C16 -> 160461 | D17: =D14+D15+D16 -> 197188.2 | E17: =E14+E15+E16 -> 260850 | F17: =C17+D17+E17 -> 618499.2 | G17: 2705296
B18: (Memo) Return Rate % | C18: ='🧮 Assumptions'!C12 -> 0.135 | D18: ='🧮 Assumptions'!D12 -> 0.12 | E18: ='🧮 Assumptions'!E12 -> 0.1 | F18: =C18+D18+E18 -> 0.355 | G18: 0.167
B20: SECTION 3: VARIABLE COSTS
B21: (Less) COGS [35.20% of Gross — locked from product CSV] | C21: =-C14*'🧮 Assumptions'!C16 -> -66528 | D21: =-D14*'🧮 Assumptions'!D16 -> -80150.4 | E21: =-E14*'🧮 Assumptions'!E16 -> -103400 | F21: =C21+D21+E21 -> -250078.4 | G21: -1165221
B22: (Less) Shipping Cost [$8.50 per order] | C22: =-C10*'🧮 Assumptions'!C17 -> -7140 | D22: =-D10*'🧮 Assumptions'!D17 -> -8415 | E22: =-E10*'🧮 Assumptions'!E17 -> -10625 | F22: =C22+D22+E22 -> -26180 | G22: -128291
B23: (Less) Merchant Fees [2.5% of Gross] | C23: =-C14*'🧮 Assumptions'!C18 -> -4725 | D23: =-D14*'🧮 Assumptions'!D18 -> -5692.5 | E23: =-E14*'🧮 Assumptions'!E18 -> -7343.75 | F23: =C23+D23+E23 -> -17761.25 | G23: -82761
B24: Gross Profit [Net - COGS - Shipping - Merchant Fees] | C24: =C17+C21+C22+C23 -> 82068 | D24: =D17+D21+D22+D23 -> 102930.3 | E24: =E17+E21+E22+E23 -> 139481.25 | F24: =C24+D24+E24 -> 324479.55 | G24: 701623
B26: SECTION 4: MARKETING
B27: (Less) Total Ad Spend | C27: =-'🧮 Assumptions'!C21 -> -55000 | D27: =-'🧮 Assumptions'!D21 -> -60000 | E27: =-'🧮 Assumptions'!E21 -> -65000 | F27: =C27+D27+E27 -> -180000 | G27: -627400
B28: Meta Spend | C28: =ABS(C27)*'🧮 Assumptions'!C22 -> 27500 | D28: =ABS(D27)*'🧮 Assumptions'!D22 -> 28800 | E28: =ABS(E27)*'🧮 Assumptions'!E22 -> 29900 | F28: =C28+D28+E28 -> 86200 | G28: 390800
B29: Google Spend | C29: =ABS(C27)*'🧮 Assumptions'!C23 -> 16500 | D29: =ABS(D27)*'🧮 Assumptions'!D23 -> 19200 | E29: =ABS(E27)*'🧮 Assumptions'!E23 -> 22100 | F29: =C29+D29+E29 -> 57800 | G29: 147200
B30: TikTok Spend | C30: =ABS(C27)*'🧮 Assumptions'!C24 -> 6600 | D30: =ABS(D27)*'🧮 Assumptions'!D24 -> 7200 | E30: =ABS(E27)*'🧮 Assumptions'!E24 -> 7800 | F30: =C30+D30+E30 -> 21600 | G30: 73100
B31: Email/SMS Spend | C31: =ABS(C27)*'🧮 Assumptions'!C25 -> 4400 | D31: =ABS(D27)*'🧮 Assumptions'!D25 -> 4800 | E31: =ABS(E27)*'🧮 Assumptions'!E25 -> 5200 | F31: =C31+D31+E31 -> 14400 | G31: 16300
B32: (Memo) MER — Marketing Efficiency Ratio | C32: =IF(ABS(C27)>0,C14/ABS(C27),0) -> 3.4363636 | D32: =IF(ABS(D27)>0,D14/ABS(D27),0) -> 3.795 | E32: =IF(ABS(E27)>0,E14/ABS(E27),0) -> 4.5192308 | F32: =C32+D32+E32 -> 11.750594 | G32: 5.28
B34: SECTION 5: CONTRIBUTION MARGIN — The Bottom Line
B35: CONTRIBUTION MARGIN $ [Net Sales - COGS - Shipping - Ad Spend] | C35: =C17+C21+C22+C27 -> 31793 | D35: =D17+D21+D22+D27 -> 48622.8 | E35: =E17+E21+E22+E27 -> 81825 | F35: =C35+D35+E35 -> 162240.8 | G35: 784384
B36: CONTRIBUTION MARGIN % [CM / Gross Sales] | C36: =IF(C14<>0,C35/C14,0) -> 0.16821693 | D36: =IF(D14<>0,D35/D14,0) -> 0.21353887 | E36: =IF(E14<>0,E35/E14,0) -> 0.27855319 | F36: =C36+D36+E36 -> 0.66030899 | G36: 0.2369
B37: CM incl. Merchant Fees $ [CM - Merchant Fees] | C37: =C24+C27 -> 27068 | D37: =D24+D27 -> 42930.3 | E37: =E24+E27 -> 74481.25 | F37: =C37+D37+E37 -> 144479.55 | G37: 701623
B38: CM incl. Merchant Fees % | C38: =IF(C14<>0,C37/C14,0) -> 0.14321693 | D38: =IF(D14<>0,D37/D14,0) -> 0.18853887 | E38: =IF(E14<>0,E37/E14,0) -> 0.25355319 | F38: =C38+D38+E38 -> 0.58530899 | G38: 0.2119
B39: CEO TARGET CHECK: CM >= 15%? | C39: =IF(C36>=0.15,"YES "&TEXT(C36,"0.0%"),"NO "&TEXT(C36,"0.0%")) -> YES 16.8% | D39: =IF(D36>=0.15,"YES "&TEXT(D36,"0.0%"),"NO "&TEXT(D36,"0.0%")) -> YES 21.4% | E39: =IF(E36>=0.15,"YES "&TEXT(E36,"0.0%"),"NO "&TEXT(E36,"0.0%")) -> YES 27.9% | F39: See individual months → | G39: 23.69% YES
B41: ANALYSIS: IS THE 15% CEO TARGET ATTAINABLE? THE MATH BEHIND THE STRATEGY
B42: Q4 2025 ACTUAL RESULT: 23.69% CM — Already beats the 15% CEO target by 8.69 percentage points.
B44: HOW WAS 23.69% ACHIEVED IN Q4?
B45: Net Sales: $2.71M on $3.31M gross (83.8% net-to-gross, reflecting 16.7% return rate + 1.6% discounts)
B46: COGS: 35.20% of gross (weighted avg from all SKUs — verified from product variant CSV, not estimated)
B47: Shipping: $128K total ($8.50 x 15,093 orders — flat rate assumption per brief)
...
